Workbook

Sheet Оплата Завод
B1: =SUBTOTAL(9,ОплатаЗавод[Сумма]) -> 2101088520
A2: Дата | B2: Сумма | C2: Платеелшик | D2: Получател
A3: 46198 | B3: 45570000 | C3: Септем Алока | D3: "CAOLS KS" MCHJ
A4: 46198 | B4: 23328000 | C4: Септем Алока | D4: "CAOLS KS" MCHJ
A5: 46202 | B5: 24624000 | C5: Септем Алока | D5: "CAOLS KS" MCHJ
A6: 46202 | B6: 23965000 | C6: Септем Алока | D6: "CAOLS KS" MCHJ
A7: 46202 | B7: 47952000 | C7: Септем Алока | D7: "CAOLS KS" MCHJ
A8: 46203 | B8: 50000000 | C8: Септем Алока | D8: "CAOLS KS" MCHJ
A9: 46203 | B9: 23872000 | C9: Септем Алока | D9: "CAOLS KS" MCHJ
A10: 46203 | B10: 22703000 | C10: Септем Алока | D10: "CAOLS KS" MCHJ
A11: 46204 | B11: 25231000 | C11: Септем Алока | D11: "CAOLS KS" MCHJ
A12: 46205 | B12: 67737600 | C12: Септем Алока | D12: "CAOLS KS" MCHJ
A13: 46205 | B13: 72394560 | C13: Септем Алока | D13: "CAOLS KS" MCHJ
A14: 46205 | B14: 73872000 | C14: Септем Алока | D14: "CAOLS KS" MCHJ
... A19: 46206 | B19: 50000000 | C19: Септем Алока | D19: "CAOLS KS" MCHJ
A20: 46206 | B20: 6000000 | C20: Нахт
A21: 46210 | B21: 50000000 | C21: Нахт пластика | D21: 9.8601901e+15

Sheet Свод Завод
A1: Сумма Товар | B1: =Товар!J2 -> 1647154250 | D1: =Товар!M2 -> 211900000
A2: Сумма Товар с паддон | B2: =Товар!N2 -> 1859054250 | D2: =B3-B1 -> 453934270
A3: Сумма Оплата Завод | B3: ='Оплата Завод'!B1 -> 2101088520
A4: Завод Остаток | B4: =B3-B2 -> 242034270 | D4: 1 | E4: Жамол | K4: 2 | L4: Арслон ога | R4: 3 | S4: Зафар ога | Y4: S | Z4: Шохрух ога
A5: Завод Остаток без паддон | B5: =D2 -> 453934270 | E5: =SUM(E7:E12) -> 4.1963016e+08 | F5: =SUM(F7:F12) -> 372450160 | G5: =SUM(G7:G12) -> -47180000 | H5: =SUM(H7:H12) -> 339 | L5: =SUM(L7:L11) -> 121824000 | M5: =SUM(M7:M11) -> 207906400 | N5: =SUM(N7:N11) -> 86082400 | O5: =SUM(O7:O12) -> 94 | S5: =SUM(S7:S11) -> 516136320 | T5: =SUM(T7:T11) -> 524219920 | U5: =SUM(U7:U11) -> 8083600 | V5: =SUM(V7:V13) -> 417 | Z5: =SUM(Z7:Z11) -> 1.1983444e+08 | AA5: =SUM(AA7:AA11) -> 119834440 | AB5: =SUM(AB7:AB11) -> 0.6208 | AC5: =SUM(AC7:AC14) -> 95
D6: Клиенты | E6: Товар | F6: Оплата | G6: Остаток | H6: Остаток Паддон | I6: Клент шопрга барди: | K6: Клиенты | L6: Товар | M6: Оплата | N6: Остаток | O6: Остаток Паддон | P6: Клент шопрга барди: | R6: Клиенты | S6: Товар | T6: Оплата | U6: Остаток | V6: Остаток Паддон | W6: Клент шопрга барди: | Y6: Клиенты | Z6: Товар | AA6: Оплата | AB6: Остаток | AC6: Остаток Паддон | AD6: Клент шопрга барди:
A7: остаток паддон: | B7: =(-1)*(H5+O5+V5+AC5) -> -945 | D7: ='1-Урганч Тамирлаш'!D1 -> 1-Урганч Тамирлаш | E7: ='1-Урганч Тамирлаш'!M5 -> 1.374996e+08 | F7: ='1-Урганч Тамирлаш'!C5 -> 130570000 | G7: ='1-Урганч Тамирлаш'!F2 -> -6929600 | H7: ='1-Урганч Тамирлаш'!K5-'1-Урганч Тамирлаш'!E5 -> 112 | I7: ='1-Урганч Тамирлаш'!I1 -> 0 | K7: ='2-Гофур Хазорасп'!D1 -> 2-Гофур Хазорасп | L7: ='2-Гофур Хазорасп'!M5 -> 121824000 | M7: ='2-Гофур Хазорасп'!C5 -> 121824000 | N7: ='2-Гофур Хазорасп'!F2 -> 0 | O7: ='2-Гофур Хазорасп'!K5-'2-Гофур Хазорасп'!E5 -> 94 | P7: ='2-Гофур Хазорасп'!I1 -> 0 | R7: ='3-Сулаймон Ога Хазарасп'!D1 -> 3-Сулаймон Ога Хазарасп | S7: ='3-Сулаймон Ога Хазарасп'!M5 -> 399254400 | T7: ='3-Сулаймон Ога Хазарасп'!C5 -> 366373200 | U7: ='3-Сулаймон Ога Хазарасп'!F2 -> -32881200 | V7: ='3-Сулаймон Ога Хазарасп'!K5-'3-Сулаймон Ога Хазарасп'!E5 -> 322 | W7: ='3-Сулаймон Ога Хазарасп'!I1 -> 25900000 | Y7: ='4-Гайрат Штб'!D1 -> 4-Гайрат Штб | Z7: ='4-Гайрат Штб'!M5 -> 49904640 | AA7: ='4-Гайрат Штб'!C5 -> 49904640 | AB7: ='4-Гайрат Штб'!F2 -> 0 | AC7: ='4-Гайрат Штб'!K5-'4-Гайрат Штб'!E5 -> 38 | AD7: ='4-Гайрат Штб'!I1 -> 0
A8: Жами остстка: | B8: =G5+N5+U5+AB5+G16 -> 68221001 | D8: ='1-Инвест Холдинг'!D1 -> 1-Инвест Холдинг | E8: ='1-Инвест Холдинг'!M5 -> 67737600 | F8: ='1-Инвест Холдинг'!C5 -> 67737600 | G8: ='1-Инвест Холдинг'!F2 -> 0 | H8: ='1-Инвест Холдинг'!K5-'1-Инвест Холдинг'!E5 -> 56 | I8: ='1-Инвест Холдинг'!I1 -> 0 | K8: ='2-Шиддат маналит'!D1 -> 2-Шиддат маналит | L8: ='2-Шиддат маналит'!M5 -> 0 | M8: ='2-Шиддат маналит'!C5 -> 86082400 | N8: ='2-Шиддат маналит'!F2 -> 86082400 | O8: ='2-Шиддат маналит'!K5-'2-Шиддат маналит'!E5 -> 0 | P8: ='2-Шиддат маналит'!I1 -> 0 | R8: ='3-Мурод ога Урганч'!D1 -> 3-Мурод ога Урганч | S8: ='3-Мурод ога Урганч'!M5 -> 47934720 | T8: ='3-Мурод ога Урганч'!C5 -> 47934720 | U8: ='3-Мурод ога Урганч'!F2 -> 0 | V8: ='3-Мурод ога Урганч'!K5-'3-Мурод ога Урганч'!E5 -> 38 | W8: ='3-Мурод ога Урганч'!I1 -> 0 | Y8: ='4-Рустам Шпик'!D1 -> 4-Рустам Шпик | Z8: ='4-Рустам Шпик'!M5 -> 69929799 | AA8: ='4-Рустам Шпик'!C5 -> 69929800 | AB8: ='4-Рустам Шпик'!F2 -> 0.6208 | AC8: ='4-Рустам Шпик'!K5-'4-Рустам Шпик'!E5 -> 57 | AD8: ='4-Рустам Шпик'!I1 -> 4000000
A9: =E4 -> Жамол | B9: =G5 -> -47180000 | D9: ='1-Нормат Умидбек'!D1 -> 1-Нормат Умидбек | E9: ='1-Нормат Умидбек'!M5 -> 72394560 | F9: ='1-Нормат Умидбек'!C5 -> 72394560 | G9: ='1-Нормат Умидбек'!F2 -> 0 | H9: ='1-Нормат Умидбек'!K5-'1-Нормат Умидбек'!E5 -> 57 | I9: ='1-Нормат Умидбек'!I1 -> 0 | R9: ='3-Сарвар ога Шовот'!D1 -> 3-Сарвар ога Шовот | S9: ='3-Сарвар ога Шовот'!M5 -> 68947200 | T9: ='3-Сарвар ога Шовот'!C5 -> 68947200 | U9: ='3-Сарвар ога Шовот'!F2 -> 0 | V9: ='3-Сарвар ога Шовот'!K5-'3-Сарвар ога Шовот'!E5 -> 57 | W9: ='3-Сарвар ога Шовот'!I1 -> 2000000 | Y9: ='4-Элликкала Бостон'!D1 -> 4-Элликкала Бостон
A10: =L4 -> Арслон ога | B10: =N5 -> 86082400 | D10: ='1-Фидато Груп'!D1 -> 1-Фидато Груп | E10: ='1-Фидато Груп'!M5 -> 93899520 | F10: ='1-Фидато Груп'!C5 -> 68916000 | G10: ='1-Фидато Груп'!F2 -> -24983520 | H10: ='1-Фидато Груп'!K5-'1-Фидато Груп'!E5 -> 76 | I10: ='1-Фидато Груп'!I1 -> 0 | R10: 3-Уктир ога Шовот | S10: ='3-Уктир ога Шовот'!M5 -> 0 | T10: ='3-Уктир ога Шовот'!C5 -> 40964800 | U10: ='3-Уктир ога Шовот'!F2 -> 40964800 | V10: ='3-Уктир ога Шовот'!K5-'3-Уктир ога Шовот'!E5 -> 0 | W10: ='3-Уктир ога Шовот'!I1 -> 0
A11: =S4 -> Зафар ога | B11: =U5 -> 8083600 | D11: ='1-Ирригатсия темир бетон'!D1 -> 1-Ирригатсия темир бетон | E11: ='1-Ирригатсия темир бетон'!M5 -> 24131520 | F11: ='1-Ирригатсия темир бетон'!C5 -> 32832000 | G11: ='1-Ирригатсия темир бетон'!F2 -> 8700480 | H11: ='1-Ирригатсия темир бетон'!K5-'1-Ирригатсия темир бетон'!E5 -> 19 | I11: ='1-Ирригатсия темир бетон'!I1 -> 0
A12: =Z4 -> Шохрух ога | B12: =AB5 -> 0.6208 | D12: ='1-Хонкага'!D1 -> 1-Хонкага | E12: ='1-Хонкага'!M5 -> 23967360 | F12: ='1-Хонкага'!C5 -> 0 | G12: ='1-Хонкага'!F2 -> -23967360 | H12: ='1-Хонкага'!K5-'1-Хонкага'!E5 -> 19 | I12: ='1-Хонкага'!I1 -> 0
D15: 5 | E15: Темур | K15: 5 | L15: Сардор ога
E16: =SUM(E18:E23) -> 367718400 | F16: =SUM(F18:F23) -> 388953400 | G16: =SUM(G18:G23) -> 21235000 | H16: =SUM(H18:H23) -> 304 | L16: =SUM(L18:L23) -> 156038400 | M16: =SUM(M18:M23) -> 202314800 | N16: =SUM(N18:N23) -> 46276400 | O16: =SUM(O18:O23) -> 129
A17: Клентларга тушилган ПУЛ | B17: =SUM(F5+M5+T5+AA5+F16+M16) -> 1815679120 | D17: Клиенты | E17: Товар | F17: Оплата | G17: Остаток | H17: Остаток Паддон | I17: Клент шопрга барди: | K17: Клиенты | L17: Товар | M17: Оплата | N17: Остаток | O17: Остаток Паддон | P17: Клент шопрга барди:
A18: Клентлар шопрга | B18: =SUM(I7:I14,I18:I24,P7:P12,W7:W12,AD7:AD12) -> 65600000 | D18: ='5-Жаср Версал'!D1 -> 5-Жасур Версал | E18: ='5-Жаср Версал'!M5 -> 206841600 | F18: ='5-Жаср Версал'!C5 -> 206841600 | G18: ='5-Жаср Версал'!F2 -> 0 | H18: ='5-Жаср Версал'!K5-'5-Жаср Версал'!E5 -> 171 | I18: ='5-Жаср Версал'!I1 -> 18600000 | K18: ='6-Уткир мини'!D1 -> 6-Уткир мини | L18: ='6-Уткир мини'!M5 -> 45964800 | M18: ='6-Уткир мини'!C5 -> 45964800 | N18: ='6-Уткир мини'!F2 -> 0 | O18: ='6-Уткир мини'!K5-'6-Уткир мини'!E5 -> 38 | P18: ='6-Уткир мини'!I1 -> 4000000
A19: Оплата лист | B19: =Оплата!R3 -> 1509053920 | D19: ='5-Мустафо машал'!D1 -> 5-Мустафо машал | E19: ='5-Мустафо машал'!M5 -> 45964800 | F19: ='5-Мустафо машал'!C5 -> 67200000 | G19: ='5-Мустафо машал'!F2 -> 21235200 | H19: ='5-Мустафо машал'!K5-'5-Мустафо машал'!E5 -> 38 | I19: ='5-Мустафо машал'!I1 -> 4200000 | K19: 6-Отабек дамирчи | L19: ='6-Отабек дамирчи'!M5 -> 45964800 | M19: ='6-Отабек дамирчи'!C5 -> 49700000 | N19: ='6-Отабек дамирчи'!F2 -> 3735200 | O19: ='6-Отабек дамирчи'!K5-'6-Отабек дамирчи'!E5 -> 38 | P19: ='6-Отабек дамирчи'!I1 -> 4700000
A20: фарк | B20: =B19-B17+B18 -> -241025200 | D20: ='5-Одилбек Ера хоус'!D1 -> 5-Одилбек Ера хоус | E20: ='5-Одилбек Ера хоус'!M5 -> 91929600 | F20: ='5-Одилбек Ера хоус'!C5 -> 91929800 | G20: ='5-Одилбек Ера хоус'!F2 -> 200 | H20: ='5-Одилбек Ера хоус'!K5-'5-Одилбек Ера хоус'!E5 -> 76 | I20: ='5-Одилбек Ера хоус'!I1 -> 8600000 | K20: 6-Мамун Университети | L20: ='6-Мамун Университети'!M5 -> 45964800 | M20: ='6-Мамун Университети'!C5 -> 104400000 | N20: ='6-Мамун Университети'!F2 -> 58435200 | O20: ='6-Мамун Университети'!K5-'6-Мамун Университети'!E5 -> 38 | P20: ='6-Мамун Университети'!I1 -> 4400000
D21: 5-Журат ога хонка | E21: ='5-Журат ога хонка'!M5 -> 22982400 | F21: ='5-Журат ога хонка'!C5 -> 22982000 | G21: ='5-Журат ога хонка'!F2 -> -400 | H21: ='5-Журат ога хонка'!K5-'5-Журат ога хонка'!E5 -> 19 | I21: ='5-Журат ога хонка'!I1 -> 2300000 | K21: 6-накд клент | L21: ='6-накд клент'!M5 -> 18144000 | M21: ='6-накд клент'!C5 -> 2250000 | N21: ='6-накд клент'!F2 -> -15894000 | O21: ='6-накд клент'!K5-'6-накд клент'!E5 -> 15 | P21: ='6-накд клент'!I1 -> 2250000
A23: Клентларга тушилган ТОВАР | B23: =E5+L5+S5+Z5+E16 -> 1.5451433e+09
A24: Товар лист | B24: =Товар!R2 -> 2.0066575e+09
A25: фарк | B25: =B24-B23 -> 461514200

Sheet Оплата
R3: =SUBTOTAL(9,Таблица15[Жами сумма]) -> 1509053920
A4: Дата | B4: Агент | C4: Клиент | D4: ПР-Сумма | E4: Плателщик | F4: Накд | G4: -5 | H4: -10 | I4: -15 | J4: -20 | K4: -50 | L4: Клик | M4: Терминал | N4: $ | O4: Курс | P4: Сумма | Q4: Прочие | R4: Жами сумма | S4: Получател | T4: Изох
A5: 46198 | B5: Жамол 22-22 | C5: Урганч Тамирлаш | D5: 45570000 | E5: URGANCH TAMIRLASH | P5: 0 | R5: =SUM(Таблица15[[#This Row],[ПР-Сумма]],Таблица15[[#This Row],[Сумма]],Таблица15[[#This Row],[Прочие]]) -> 45570000
A6: 46198 | B6: Зафар ога | C6: Сулаймон Ога Хазарасп | D6: 23328000 | E6: HAZORASP MUHAMMAD | P6: 0 | R6: =SUM(Таблица15[[#This Row],[ПР-Сумма]],Таблица15[[#This Row],[Сумма]],Таблица15[[#This Row],[Прочие]]) -> 23328000
A7: 46202 | B7: Зафар ога | C7: Сулаймон Ога Хазарасп | D7: 24624000 | E7: "A-SIA HOUSE" MCHJ | P7: 0 | R7: =SUM(Таблица15[[#This Row],[ПР-Сумма]],Таблица15[[#This Row],[Сумма]],Таблица15[[#This Row],[Прочие]]) -> 24624000
A8: 46202 | B8: Шохрух ога | C8: Рустам Шпик | D8: 23965000 | E8: "Ифтихор" хусусий корхонаси | P8: 0 | R8: =SUM(Таблица15[[#This Row],[ПР-Сумма]],Таблица15[[#This Row],[Сумма]],Таблица15[[#This Row],[Прочие]]) -> 23965000
A9: 46202 | B9: Арслон ога | C9: Гофур хазорасп | D9: 47952000 | E9: "EZVIZ CITY"Mchj | P9: 0 | R9: =SUM(Таблица15[[#This Row],[ПР-Сумма]],Таблица15[[#This Row],[Сумма]],Таблица15[[#This Row],[Прочие]]) -> 47952000
A10: 46203 | B10: Арслон ога | C10: Сулаймон Ога Хазарасп | D10: 73872000 | E10: Xazorasp Ipoteka Qurilish мчж | P10: 0 | R10: =SUM(Таблица15[[#This Row],[ПР-Сумма]],Таблица15[[#This Row],[Сумма]],Таблица15[[#This Row],[Прочие]]) -> 73872000
A11: 46203 | B11: Жамол 22-22 | C11: Фидато Груп | D11: 22703000 | E11: ООО "FIDATO GROUP" | P11: 0 | R11: =SUM(Таблица15[[#This Row],[ПР-Сумма]],Таблица15[[#This Row],[Сумма]],Таблица15[[#This Row],[Прочие]]) -> 22703000
A12: 46203 | B12: Жамол 22-22 | C12: Фидато Груп | D12: 25231000 | E12: ООО "FIDATO GROUP" | P12: 0 | R12: =SUM(Таблица15[[#This Row],[ПР-Сумма]],Таблица15[[#This Row],[Сумма]],Таблица15[[#This Row],[Прочие]]) -> 25231000
A13: 46205 | B13: Жамол 22-22 | C13: Инвест Холдинг | D13: 67737600 | E13: Хоразм Инвест Холдинг | P13: 0 | R13: =SUM(Таблица15[[#This Row],[ПР-Сумма]],Таблица15[[#This Row],[Сумма]],Таблица15[[#This Row],[Прочие]]) -> 67737600
A14: 46205 | B14: Жамол 22-22 | C14: NORMAT UMIDBEK | D14: 72394560 | E14: NORMAT UMIDBEK MCHJ | P14: 0 | R14: =SUM(Таблица15[[#This Row],[ПР-Сумма]],Таблица15[[#This Row],[Сумма]],Таблица15[[#This Row],[Прочие]]) -> 72394560
A15: 46205 | B15: Жамол 22-22 | C15: Гофур Хазорасп | D15: 73872000 | E15: "DOMEX GROUP" Mchj | P15: 0 | R15: =SUM(Таблица15[[#This Row],[ПР-Сумма]],Таблица15[[#This Row],[Сумма]],Таблица15[[#This Row],[Прочие]]) -> 73872000
A16: 46206 | B16: Зафар ога | C16: Мурод ога Урганч | D16: 47934720 | E16: "Ulgircha savdo diyor" MCHJ | P16: 0 | R16: =SUM(Таблица15[[#This Row],[ПР-Сумма]],Таблица15[[#This Row],[Сумма]],Таблица15[[#This Row],[Прочие]]) -> 47934720
... A25: 46209 | B25: Зафар ога | C25: Сулаймон Ога Хазарасп | D25: 61447200 | E25: HAZORASP BINOKOR USTA MChJ | P25: 0 | R25: =SUM(Таблица15[[#This Row],[ПР-Сумма]],Таблица15[[#This Row],[Сумма]],Таблица15[[#This Row],[Прочие]]) -> 61447200
A26: 46209 | B26: Арслон ога | C26: Шиддат маналит | D26: 2100000 | E26: SHIDDAT MONOLIT MCHJ | P26: 0 | R26: =SUM(Таблица15[[#This Row],[ПР-Сумма]],Таблица15[[#This Row],[Сумма]],Таблица15[[#This Row],[Прочие]]) -> 2100000 | T26: бир машин газаблок даставка учун ташоди
A27: 46209 | B27: Темур | C27: Мустафо машал | D27: 21000000 | E27: "SHUKR BARAKA" MCHJ | P27: 0 | R27: =SUM(Таблица15[[#This Row],[ПР-Сумма]],Таблица15[[#This Row],[Сумма]],Таблица15[[#This Row],[Прочие]]) -> 21000000
A28: 46210 | B28: Сардор ога | C28: Уткир мини | D28: 40000000 | E28: Коровул курилиш монтаж | P28: 0 | R28: =SUM(Таблица15[[#This Row],[ПР-Сумма]],Таблица15[[#This Row],[Сумма]],Таблица15[[#This Row],[Прочие]]) -> 40000000 | S28: Септем семент
A29: 46210 | B29: Шохрух ога | C29: БУНЕДКОР | D29: 41964800 | E29: "БУНЕДКОР" МЧЖ | P29: 0 | R29: =SUM(Таблица15[[#This Row],[ПР-Сумма]],Таблица15[[#This Row],[Сумма]],Таблица15[[#This Row],[Прочие]]) -> 41964800 | S29: Септем семент
A30: 46210 | B30: Зафар ога | C30: Сулаймон ога Хазарасп | D30: 41965000 | E30: HAZORASP MUHAMMAD XO'JA MChJ | P30: 0 | R30: =SUM(Таблица15[[#This Row],[ПР-Сумма]],Таблица15[[#This Row],[Сумма]],Таблица15[[#This Row],[Прочие]]) -> 41965000 | S30: Септем семент
A31: 46211 | B31: Шохрух ога | C31: Жамол 22-22 | D31: 20982000 | E31: ООО "FIDATO GROUP" | P31: 0 | R31: =SUM(Таблица15[[#This Row],[ПР-Сумма]],Таблица15[[#This Row],[Сумма]],Таблица15[[#This Row],[Прочие]]) -> 20982000 | S31: Септем семент
A32: 46211 | B32: Сардор ога | C32: Уткир мини | D32: 1964800 | E32: КОРОВУЛ КУРИЛИШ МОНТАЖ ХК | P32: 0 | R32: =SUM(Таблица15[[#This Row],[ПР-Сумма]],Таблица15[[#This Row],[Сумма]],Таблица15[[#This Row],[Прочие]]) -> 1964800 | S32: Септем семент
A33: 46211 | B33: Шохрух ога | C33: Жамол 22-22 | D33: 32832000 | E33: IRRIGATSIYA TEMIR BETON QURILISH | P33: 0 | R33: =SUM(Таблица15[[#This Row],[ПР-Сумма]],Таблица15[[#This Row],[Сумма]],Таблица15[[#This Row],[Прочие]]) -> 32832000 | S33: Септем семент
A34: 46211 | B34: Арслон ога | C34: шиддат маналит | D34: 63000000 | E34: SHIDDAT MONOLIT MCHJ | P34: 0 | R34: =SUM(Таблица15[[#This Row],[ПР-Сумма]],Таблица15[[#This Row],[Сумма]],Таблица15[[#This Row],[Прочие]]) -> 63000000 | S34: Септем семент
A35: 46212 | B35: Темур ога | C35: Одилбек ера | D35: 41964800 | E35: "ERA MOTOR'S" MCHJ | P35: 0 | R35: =SUM(Таблица15[[#This Row],[ПР-Сумма]],Таблица15[[#This Row],[Сумма]],Таблица15[[#This Row],[Прочие]]) -> 41964800 | S35: Септем семент
A36: 46212 | B36: Темур ога | C36: Мустофо курилиш Машал | D36: 21000000 | E36: ``SHUKR BARAKA``MCHJ | P36: 0 | R36: =SUM(Таблица15[[#This Row],[ПР-Сумма]],Таблица15[[#This Row],[Сумма]],Таблица15[[#This Row],[Прочие]]) -> 21000000 | S36: Септем семент
A37: 46212 | B37: Сардор ога | C37: Отабек дамирчи | D37: 45000000 | E37: "Qodiriy Construction" Масъулияти Чекланган Жамият | P37: 0 | R37: =SUM(Таблица15[[#This Row],[ПР-Сумма]],Таблица15[[#This Row],[Сумма]],Таблица15[[#This Row],[Прочие]]) -> 45000000 | S37: Септем семент
A38: 46212 | B38: Темур ога | C38: Журат ога хонка | D38: 20682000 | E38: "VATANPARVARLIK YOSHLAR KELAJAGI" MCHJ | P38: 0 | R38: =SUM(Таблица15[[#This Row],[ПР-Сумма]],Таблица15[[#This Row],[Сумма]],Таблица15[[#This Row],[Прочие]]) -> 20682000 | S38: Септем семент
A39: 46213 | B39: Зафар ога | C39: Сулаймон ога Хазарасп | D39: 20810000 | E39: OOO QILICH-AMIN-NIYAZ | P39: 0 | R39: =SUM(Таблица15[[#This Row],[ПР-Сумма]],Таблица15[[#This Row],[Сумма]],Таблица15[[#This Row],[Прочие]]) -> 20810000 | S39: Септем семент
... A42: 46213 | B42: Зафар ога | C42: Сулаймон ога Хазарасп | D42: 46620000 | E42: HAZORASP BINOKOR USTA MChJ | P42: 0 | R42: =SUM(Таблица15[[#This Row],[ПР-Сумма]],Таблица15[[#This Row],[Сумма]],Таблица15[[#This Row],[Прочие]]) -> 46620000 | S42: Септем семент
P43: 0 | R43: =SUM(Таблица15[[#This Row],[ПР-Сумма]],Таблица15[[#This Row],[Сумма]],Таблица15[[#This Row],[Прочие]]) -> 0
P44: 0 | R44: =SUM(Таблица15[[#This Row],[ПР-Сумма]],Таблица15[[#This Row],[Сумма]],Таблица15[[#This Row],[Прочие]]) -> 0
P45: 0 | R45: =SUM(Таблица15[[#This Row],[ПР-Сумма]],Таблица15[[#This Row],[Сумма]],Таблица15[[#This Row],[Прочие]]) -> 0
P46: 0 | R46: =SUM(Таблица15[[#This Row],[ПР-Сумма]],Таблица15[[#This Row],[Сумма]],Таблица15[[#This Row],[Прочие]]) -> 0
P47: 0 | R47: =SUM(Таблица15[[#This Row],[ПР-Сумма]],Таблица15[[#This Row],[Сумма]],Таблица15[[#This Row],[Прочие]]) -> 0
P48: 0 | R48: =SUM(Таблица15[[#This Row],[ПР-Сумма]],Таблица15[[#This Row],[Сумма]],Таблица15[[#This Row],[Прочие]]) -> 0
P49: 0 | R49: =SUM(Таблица15[[#This Row],[ПР-Сумма]],Таблица15[[#This Row],[Сумма]],Таблица15[[#This Row],[Прочие]]) -> 0
P50: 0 | R50: =SUM(Таблица15[[#This Row],[ПР-Сумма]],Таблица15[[#This Row],[Сумма]],Таблица15[[#This Row],[Прочие]]) -> 0
P51: 0 | R51: =SUM(Таблица15[[#This Row],[ПР-Сумма]],Таблица15[[#This Row],[Сумма]],Таблица15[[#This Row],[Прочие]]) -> 0
P52: 0 | R52: =SUM(Таблица15[[#This Row],[ПР-Сумма]],Таблица15[[#This Row],[Сумма]],Таблица15[[#This Row],[Прочие]]) -> 0
...

Sheet Товар
H2: =SUBTOTAL(9,Таблица1[Блок Куб]) -> 2817.578 | J2: =SUBTOTAL(9,Таблица1[Сумма Приход]) -> 1647154250 | K2: =SUBTOTAL(9,Таблица1[Поддон Шт]) -> 1630 | M2: =SUBTOTAL(9,Таблица1[Сумма Поддон]) -> 211900000 | N2: =SUBTOTAL(9,Таблица1[Блок+ Поддон]) -> 1859054250 | R2: =SUBTOTAL(9,Таблица1[Сумма Продажа]) -> 2.0066575e+09 | S2: =SUBTOTAL(9,Таблица1[Расход Авто]) -> 68100000 | T2: =SUBTOTAL(9,Таблица1[Общая прибль]) -> 3.5950327e+08 | W2: =R2-J2 -> 3.5950327e+08
A3: В-о | B3: Поставшик | C3: Агент | D3: Клиент | E3: Дата | F3: № авто | G3: Размер | H3: Блок Куб | I3: Цена Приход | J3: Сумма Приход | K3: Поддон Шт | L3: Цена Поддон | M3: Сумма Поддон | N3: Блок+ Поддон | O3: Цена Продажа | P3: Разница | Q3: ИЗОХ | R3: Сумма Продажа | S3: Расход Авто | T3: Общая прибль | U3: Авто услу барлдми?
A4: 1 | B4: Газоблок | C4: Жамол 22-22 | D4: Урганч Тамирлаш | E4: 46197 | F4: 95 G 851 NA | G4: 600x300x200 | H4: 31.104 | I4: 500000 | J4: =Таблица1[[#This Row],[Блок Куб]]*Таблица1[[#This Row],[Цена Приход]] -> 15552000 | K4: 18 | L4: 130000 | M4: =Таблица1[[#This Row],[Поддон Шт]]*Таблица1[[#This Row],[Цена Поддон]] -> 2340000 | N4: =Таблица1[[#This Row],[Сумма Приход]]+Таблица1[[#This Row],[Сумма Поддон]] -> 17892000 | O4: 732542.44 | P4: =(Таблица1[[#This Row],[Цена Продажа]]+Таблица1[[#This Row],[Цена Поддон]])-Таблица1[[#This Row],[Цена Приход]] -> 362542.44 | Q4: Фойда | R4: =Таблица1[[#This Row],[Блок Куб]]*Таблица1[[#This Row],[Цена Продажа]] -> 22785000 | S4: 2000000 | T4: =Таблица1[[#This Row],[Сумма Продажа]]-Таблица1[[#This Row],[Сумма Приход]] -> 7233000 | U4: Туланди
A5: =A4+1 -> 2 | B5: Газоблок | C5: Жамол 22-22 | D5: Урганч Тамирлаш | E5: 46197 | F5: 40 Y 173 KB | G5: 600x300x200 | H5: 31.104 | I5: 500000 | J5: =Таблица1[[#This Row],[Блок Куб]]*Таблица1[[#This Row],[Цена Приход]] -> 15552000 | K5: 18 | L5: 130000 | M5: =Таблица1[[#This Row],[Поддон Шт]]*Таблица1[[#This Row],[Цена Поддон]] -> 2340000 | N5: =Таблица1[[#This Row],[Сумма Приход]]+Таблица1[[#This Row],[Сумма Поддон]] -> 17892000 | O5: 732542.44 | P5: =(Таблица1[[#This Row],[Цена Продажа]]+Таблица1[[#This Row],[Цена Поддон]])-Таблица1[[#This Row],[Цена Приход]] -> 362542.44 | Q5: Фойда | R5: =Таблица1[[#This Row],[Блок Куб]]*Таблица1[[#This Row],[Цена Продажа]] -> 22785000 | S5: 2000000 | T5: =Таблица1[[#This Row],[Сумма Продажа]]-Таблица1[[#This Row],[Сумма Приход]] -> 7233000 | U5: Туланди
A6: =A5+1 -> 3 | B6: Газоблок | C6: Жамол 22-22 | D6: Инвест Холдинг | E6: 46197 | F6: 90 X 700 CA | G6: 600x300x200 | H6: 31.104 | I6: 500000 | J6: =Таблица1[[#This Row],[Блок Куб]]*Таблица1[[#This Row],[Цена Приход]] -> 15552000 | K6: 18 | L6: 130000 | M6: =Таблица1[[#This Row],[Поддон Шт]]*Таблица1[[#This Row],[Цена Поддон]] -> 2340000 | N6: =Таблица1[[#This Row],[Сумма Приход]]+Таблица1[[#This Row],[Сумма Поддон]] -> 17892000 | O6: 700000 | P6: =(Таблица1[[#This Row],[Цена Продажа]]+Таблица1[[#This Row],[Цена Поддон]])-Таблица1[[#This Row],[Цена Приход]] -> 330000 | Q6: Фойда | R6: =Таблица1[[#This Row],[Блок Куб]]*Таблица1[[#This Row],[Цена Продажа]] -> 21772800 | S6: 2000000 | T6: =Таблица1[[#This Row],[Сумма Продажа]]-Таблица1[[#This Row],[Сумма Приход]] -> 6220800 | U6: Туланди
A7: =A6+1 -> 4 | B7: Газоблок | C7: Зафар ога | D7: Сулаймон Ога Хазарасп | E7: 46197 | F7: 90 G 991 FA | G7: 600x300x200 | H7: 31.104 | I7: 500000 | J7: =Таблица1[[#This Row],[Блок Куб]]*Таблица1[[#This Row],[Цена Приход]] -> 15552000 | K7: 18 | L7: 130000 | M7: =Таблица1[[#This Row],[Поддон Шт]]*Таблица1[[#This Row],[Цена Поддон]] -> 2340000 | N7: =Таблица1[[#This Row],[Сумма Приход]]+Таблица1[[#This Row],[Сумма Поддон]] -> 17892000 | O7: 750000 | P7: =(Таблица1[[#This Row],[Цена Продажа]]+Таблица1[[#This Row],[Цена Поддон]])-Таблица1[[#This Row],[Цена Приход]] -> 380000 | Q7: Фойда | R7: =Таблица1[[#This Row],[Блок Куб]]*Таблица1[[#This Row],[Цена Продажа]] -> 23328000 | S7: 2000000 | T7: =Таблица1[[#This Row],[Сумма Продажа]]-Таблица1[[#This Row],[Сумма Приход]] -> 7776000 | U7: Туланди
A8: =A7+1 -> 5 | B8: Газоблок | C8: Жамол 22-22 | D8: Инвест Холдинг | E8: 46197 | F8: 90 G 429 CA | G8: 600x300x200 | H8: 32.832 | I8: 500000 | J8: =Таблица1[[#This Row],[Блок Куб]]*Таблица1[[#This Row],[Цена Приход]] -> 16416000 | K8: 19 | L8: 130000 | M8: =Таблица1[[#This Row],[Поддон Шт]]*Таблица1[[#This Row],[Цена Поддон]] -> 2470000 | N8: =Таблица1[[#This Row],[Сумма Приход]]+Таблица1[[#This Row],[Сумма Поддон]] -> 18886000 | O8: 700000 | P8: =(Таблица1[[#This Row],[Цена Продажа]]+Таблица1[[#This Row],[Цена Поддон]])-Таблица1[[#This Row],[Цена Приход]] -> 330000 | Q8: Фойда | R8: =Таблица1[[#This Row],[Блок Куб]]*Таблица1[[#This Row],[Цена Продажа]] -> 22982400 | S8: 2000000 | T8: =Таблица1[[#This Row],[Сумма Продажа]]-Таблица1[[#This Row],[Сумма Приход]] -> 6566400 | U8: Туланди
A9: =A8+1 -> 6 | B9: Газоблок | C9: Жамол 22-22 | D9: Инвест Холдинг | E9: 46198 | F9: 30 N 113 MB | G9: 600x300x200 | H9: 32.832 | I9: 500000 | J9: =Таблица1[[#This Row],[Блок Куб]]*Таблица1[[#This Row],[Цена Приход]] -> 16416000 | K9: 19 | L9: 130000 | M9: =Таблица1[[#This Row],[Поддон Шт]]*Таблица1[[#This Row],[Цена Поддон]] -> 2470000 | N9: =Таблица1[[#This Row],[Сумма Приход]]+Таблица1[[#This Row],[Сумма Поддон]] -> 18886000 | O9: 700000 | P9: =Таблица1[[#This Row],[Цена Продажа]]-Таблица1[[#This Row],[Цена Приход]] -> 200000 | Q9: Фойда | R9: =Таблица1[[#This Row],[Блок Куб]]*Таблица1[[#This Row],[Цена Продажа]] -> 22982400 | S9: 2000000 | T9: =Таблица1[[#This Row],[Сумма Продажа]]-Таблица1[[#This Row],[Сумма Приход]] -> 6566400 | U9: Туланди
A10: =A9+1 -> 7 | B10: Газоблок | C10: Жамол 22-22 | D10: Нормат Умидбек | E10: 46198 | F10: 50 R 575 CB | G10: 600x300x200 | H10: 32.832 | I10: 500000 | J10: =Таблица1[[#This Row],[Блок Куб]]*Таблица1[[#This Row],[Цена Приход]] -> 16416000 | K10: 19 | L10: 130000 | M10: =Таблица1[[#This Row],[Поддон Шт]]*Таблица1[[#This Row],[Цена Поддон]] -> 2470000 | N10: =Таблица1[[#This Row],[Сумма Приход]]+Таблица1[[#This Row],[Сумма Поддон]] -> 18886000 | O10: 735000 | P10: =Таблица1[[#This Row],[Цена Продажа]]-Таблица1[[#This Row],[Цена Приход]] -> 235000 | Q10: Фойда | R10: =Таблица1[[#This Row],[Блок Куб]]*Таблица1[[#This Row],[Цена Продажа]] -> 24131520 | S10: 2000000 | T10: =Таблица1[[#This Row],[Сумма Продажа]]-Таблица1[[#This Row],[Сумма Приход]] -> 7715520 | U10: Туланди
A11: =A10+1 -> 8 | B11: Газоблок | C11: Жамол 22-22 | D11: Нормат Умидбек | E11: 46198 | F11: 30 784 WBA | G11: 600x300x200 | H11: 32.832 | I11: 500000 | J11: =Таблица1[[#This Row],[Блок Куб]]*Таблица1[[#This Row],[Цена Приход]] -> 16416000 | K11: 19 | L11: 130000 | M11: =Таблица1[[#This Row],[Поддон Шт]]*Таблица1[[#This Row],[Цена Поддон]] -> 2470000 | N11: =Таблица1[[#This Row],[Сумма Приход]]+Таблица1[[#This Row],[Сумма Поддон]] -> 18886000 | O11: 735000 | P11: =Таблица1[[#This Row],[Цена Продажа]]-Таблица1[[#This Row],[Цена Приход]] -> 235000 | Q11: Фойда | R11: =Таблица1[[#This Row],[Блок Куб]]*Таблица1[[#This Row],[Цена Продажа]] -> 24131520 | S11: 2000000 | T11: =Таблица1[[#This Row],[Сумма Продажа]]-Таблица1[[#This Row],[Сумма Приход]] -> 7715520 | U11: Туланди
A12: =A11+1 -> 9 | B12: Газоблок | C12: Жамол 22-22 | D12: Нормат Умидбек | E12: 46198 | F12: VI-004-KT | G12: 600x300x200 | H12: 32.832 | I12: 500000 | J12: =Таблица1[[#This Row],[Блок Куб]]*Таблица1[[#This Row],[Цена Приход]] -> 16416000 | K12: 19 | L12: 130000 | M12: =Таблица1[[#This Row],[Поддон Шт]]*Таблица1[[#This Row],[Цена Поддон]] -> 2470000 | N12: =Таблица1[[#This Row],[Сумма Приход]]+Таблица1[[#This Row],[Сумма Поддон]] -> 18886000 | O12: 735000 | P12: =Таблица1[[#This Row],[Цена Продажа]]-Таблица1[[#This Row],[Цена Приход]] -> 235000 | Q12: Фойда | R12: =Таблица1[[#This Row],[Блок Куб]]*Таблица1[[#This Row],[Цена Продажа]] -> 24131520 | S12: 2000000 | T12: =Таблица1[[#This Row],[Сумма Продажа]]-Таблица1[[#This Row],[Сумма Приход]] -> 7715520 | U12: Туланди
A13: =A12+1 -> 10 | B13: Газоблок | C13: Арслон ога | D13: Гофур Хазорасп | E13: 46198 | F13: 01 U 917 XC | G13: 600x300x200 | H13: 32.832 | I13: 500000 | J13: =Таблица1[[#This Row],[Блок Куб]]*Таблица1[[#This Row],[Цена Приход]] -> 16416000 | K13: 19 | L13: 130000 | M13: =Таблица1[[#This Row],[Поддон Шт]]*Таблица1[[#This Row],[Цена Поддон]] -> 2470000 | N13: =Таблица1[[#This Row],[Сумма Приход]]+Таблица1[[#This Row],[Сумма Поддон]] -> 18886000 | O13: 750000 | P13: =Таблица1[[#This Row],[Цена Продажа]]-Таблица1[[#This Row],[Цена Приход]] -> 250000 | Q13: Фойда | R13: =Таблица1[[#This Row],[Блок Куб]]*Таблица1[[#This Row],[Цена Продажа]] -> 24624000 | S13: 2500000 | T13: =Таблица1[[#This Row],[Сумма Продажа]]-Таблица1[[#This Row],[Сумма Приход]] -> 8208000 | U13: Туланди
A14: =A13+1 -> 11 | B14: Газоблок | C14: Арслон ога | D14: Гофур Хазорасп | E14: 46198 | F14: 95 194 LBA | G14: 600x300x200 | H14: 31.104 | I14: 500000 | J14: =Таблица1[[#This Row],[Блок Куб]]*Таблица1[[#This Row],[Цена Приход]] -> 15552000 | K14: 18 | L14: 130000 | M14: =Таблица1[[#This Row],[Поддон Шт]]*Таблица1[[#This Row],[Цена Поддон]] -> 2340000 | N14: =Таблица1[[#This Row],[Сумма Приход]]+Таблица1[[#This Row],[Сумма Поддон]] -> 17892000 | O14: 750000 | P14: =Таблица1[[#This Row],[Цена Продажа]]-Таблица1[[#This Row],[Цена Приход]] -> 250000 | Q14: Фойда | R14: =Таблица1[[#This Row],[Блок Куб]]*Таблица1[[#This Row],[Цена Продажа]] -> 23328000 | S14: 2500000 | T14: =Таблица1[[#This Row],[Сумма Продажа]]-Таблица1[[#This Row],[Сумма Приход]] -> 7776000 | U14: Туланди
A15: =A14+1 -> 12 | B15: Газоблок | C15: Зафар ога | D15: Сулаймон Ога Хазарасп | E15: 46200 | F15: 40 W 910 SB | G15: 600x300x100 | H15: 32.832 | I15: 500000 | J15: =Таблица1[[#This Row],[Блок Куб]]*Таблица1[[#This Row],[Цена Приход]] -> 16416000 | K15: 19 | L15: 130000 | M15: =Таблица1[[#This Row],[Поддон Шт]]*Таблица1[[#This Row],[Цена Поддон]] -> 2470000 | N15: =Таблица1[[#This Row],[Сумма Приход]]+Таблица1[[#This Row],[Сумма Поддон]] -> 18886000 | O15: 750000 | P15: =Таблица1[[#This Row],[Цена Продажа]]-Таблица1[[#This Row],[Цена Приход]] -> 250000 | Q15: Фойда | R15: =Таблица1[[#This Row],[Блок Куб]]*Таблица1[[#This Row],[Цена Продажа]] -> 24624000 | S15: 2500000 | T15: =Таблица1[[#This Row],[Сумма Продажа]]-Таблица1[[#This Row],[Сумма Приход]] -> 8208000 | U15: Туланди
A16: =A15+1 -> 13 | B16: Газоблок | C16: Зафар ога | D16: Сулаймон Ога Хазарасп | E16: 46200 | F16: 90 Z 688 AB | G16: 600x300x100 | H16: 32.832 | I16: 500000 | J16: =Таблица1[[#This Row],[Блок Куб]]*Таблица1[[#This Row],[Цена Приход]] -> 16416000 | K16: 19 | L16: 130000 | M16: =Таблица1[[#This Row],[Поддон Шт]]*Таблица1[[#This Row],[Цена Поддон]] -> 2470000 | N16: =Таблица1[[#This Row],[Сумма Приход]]+Таблица1[[#This Row],[Сумма Поддон]] -> 18886000 | O16: 750000 | P16: =Таблица1[[#This Row],[Цена Продажа]]-Таблица1[[#This Row],[Цена Приход]] -> 250000 | Q16: Фойда | R16: =Таблица1[[#This Row],[Блок Куб]]*Таблица1[[#This Row],[Цена Продажа]] -> 24624000 | S16: 2000000 | T16: =Таблица1[[#This Row],[Сумма Продажа]]-Таблица1[[#This Row],[Сумма Приход]] -> 8208000 | U16: Туланди
A17: =A16+1 -> 14 | B17: Газоблок | C17: Зафар ога | D17: Сулаймон Ога Хазарасп | E17: 46200 | F17: 95 617 MBA | G17: 600x300x200 | H17: 32.832 | I17: 500000 | J17: =Таблица1[[#This Row],[Блок Куб]]*Таблица1[[#This Row],[Цена Приход]] -> 16416000 | K17: 19 | L17: 130000 | M17: =Таблица1[[#This Row],[Поддон Шт]]*Таблица1[[#This Row],[Цена Поддон]] -> 2470000 | N17: =Таблица1[[#This Row],[Сумма Приход]]+Таблица1[[#This Row],[Сумма Поддон]] -> 18886000 | O17: 750000 | P17: =Таблица1[[#This Row],[Цена Продажа]]-Таблица1[[#This Row],[Цена Приход]] -> 250000 | Q17: Фойда | R17: =Таблица1[[#This Row],[Блок Куб]]*Таблица1[[#This Row],[Цена Продажа]] -> 24624000 | S17: 2000000 | T17: =Таблица1[[#This Row],[Сумма Продажа]]-Таблица1[[#This Row],[Сумма Приход]] -> 8208000 | U17: Туланди
A18: =A17+1 -> 15 | B18: Газоблок | C18: Зафар ога | D18: Сулаймон Ога Хазарасп | E18: 46200 | F18: 40 148 ECA | G18: 600x300x200 | H18: 32.832 | I18: 500000 | J18: =Таблица1[[#This Row],[Блок Куб]]*Таблица1[[#This Row],[Цена Приход]] -> 16416000 | K18: 19 | L18: 130000 | M18: =Таблица1[[#This Row],[Поддон Шт]]*Таблица1[[#This Row],[Цена Поддон]] -> 2470000 | N18: =Таблица1[[#This Row],[Сумма Приход]]+Таблица1[[#This Row],[Сумма Поддон]] -> 18886000 | O18: 750000 | P18: =Таблица1[[#This Row],[Цена Продажа]]-Таблица1[[#This Row],[Цена Приход]] -> 250000 | Q18: Фойда | R18: =Таблица1[[#This Row],[Блок Куб]]*Таблица1[[#This Row],[Цена Продажа]] -> 24624000 | S18: 2000000 | T18: =Таблица1[[#This Row],[Сумма Продажа]]-Таблица1[[#This Row],[Сумма Приход]] -> 8208000 | U18: Туланди
A19: =A18+1 -> 16 | B19: Газоблок | C19: Шохрух ога | D19: Гайрат Штб | E19: 46200 | F19: 90 919 LBA | G19: 600x300x200 | H19: 32.832 | I19: 500000 | J19: =Таблица1[[#This Row],[Блок Куб]]*Таблица1[[#This Row],[Цена Приход]] -> 16416000 | K19: 19 | L19: 130000 | M19: =Таблица1[[#This Row],[Поддон Шт]]*Таблица1[[#This Row],[Цена Поддон]] -> 2470000 | N19: =Таблица1[[#This Row],[Сумма Приход]]+Таблица1[[#This Row],[Сумма Поддон]] -> 18886000 | O19: 760000 | P19: =Таблица1[[#This Row],[Цена Продажа]]-Таблица1[[#This Row],[Цена Приход]] -> 260000 | Q19: Фойда | R19: =Таблица1[[#This Row],[Блок Куб]]*Таблица1[[#This Row],[Цена Продажа]] -> 24952320 | S19: 2000000 | T19: =Таблица1[[#This Row],[Сумма Продажа]]-Таблица1[[#This Row],[Сумма Приход]] -> 8536320 | U19: Туланди
A20: =A19+1 -> 17 | B20: Газоблок | C20: Шохрух ога | D20: Рустам Шпик | E20: 46200 | F20: 90 X 700 CA | G20: 600x300x200 | H20: 32.832 | I20: 500000 | J20: =Таблица1[[#This Row],[Блок Куб]]*Таблица1[[#This Row],[Цена Приход]] -> 16416000 | K20: 19 | L20: 130000 | M20: =Таблица1[[#This Row],[Поддон Шт]]*Таблица1[[#This Row],[Цена Поддон]] -> 2470000 | N20: =Таблица1[[#This Row],[Сумма Приход]]+Таблица1[[#This Row],[Сумма Поддон]] -> 18886000 | O20: 729928.1 | P20: =Таблица1[[#This Row],[Цена Продажа]]-Таблица1[[#This Row],[Цена Приход]] -> 229928.1 | Q20: Фойда | R20: =Таблица1[[#This Row],[Блок Куб]]*Таблица1[[#This Row],[Цена Продажа]] -> 23964999 | S20: 2000000 | T20: =Таблица1[[#This Row],[Сумма Продажа]]-Таблица1[[#This Row],[Сумма Приход]] -> 7548999.4 | U20: Туланди
... A30: =A29+1 -> 27 | B30: Газоблок | C30: Арслон ога | D30: Гофур Хазорасп | E30: 46204 | F30: 70 Y 119 GB | G30: 600x300x100 | H30: 32.832 | I30: 500000 | J30: =Таблица1[[#This Row],[Блок Куб]]*Таблица1[[#This Row],[Цена Приход]] -> 16416000 | K30: 19 | L30: 130000 | M30: =Таблица1[[#This Row],[Поддон Шт]]*Таблица1[[#This Row],[Цена Поддон]] -> 2470000 | N30: =Таблица1[[#This Row],[Сумма Приход]]+Таблица1[[#This Row],[Сумма Поддон]] -> 18886000 | O30: 750000 | P30: =Таблица1[[#This Row],[Цена Продажа]]-Таблица1[[#This Row],[Цена Приход]] -> 250000 | Q30: Фойда | R30: =Таблица1[[#This Row],[Блок Куб]]*Таблица1[[#This Row],[Цена Продажа]] -> 24624000 | S30: 2550000 | T30: =Таблица1[[#This Row],[Сумма Продажа]]-Таблица1[[#This Row],[Сумма Приход]] -> 8208000 | U30: Туланди
A31: =A30+1 -> 28 | B31: Газоблок | C31: Жамол 22-22 | D31: Фидато Груп | E31: 46205 | F31: 90 S 954 OA | G31: 600x300x100 | H31: 32.832 | I31: 625000 | J31: =Таблица1[[#This Row],[Блок Куб]]*Таблица1[[#This Row],[Цена Приход]] -> 20520000 | K31: 19 | L31: 130000 | M31: =Таблица1[[#This Row],[Поддон Шт]]*Таблица1[[#This Row],[Цена Поддон]] -> 2470000 | N31: =Таблица1[[#This Row],[Сумма Приход]]+Таблица1[[#This Row],[Сумма Поддон]] -> 22990000 | O31: 730000 | P31: =Таблица1[[#This Row],[Цена Продажа]]-Таблица1[[#This Row],[Цена Приход]] -> 105000 | Q31: Фойда | R31: =Таблица1[[#This Row],[Блок Куб]]*Таблица1[[#This Row],[Цена Продажа]] -> 23967360 | S31: 2000000 | T31: =Таблица1[[#This Row],[Сумма Продажа]]-Таблица1[[#This Row],[Сумма Приход]] -> 3447360 | U31: 46206
A32: =A31+1 -> 29 | B32: Газоблок | C32: Жамол 22-22 | D32: Урганч Тамирлаш | E32: 46206 | F32: 40 F 105 RB | G32: 600x300x200 | H32: 32.832 | I32: 625000 | J32: =Таблица1[[#This Row],[Блок Куб]]*Таблица1[[#This Row],[Цена Приход]] -> 20520000 | K32: 19 | L32: 130000 | M32: =Таблица1[[#This Row],[Поддон Шт]]*Таблица1[[#This Row],[Цена Поддон]] -> 2470000 | N32: =Таблица1[[#This Row],[Сумма Приход]]+Таблица1[[#This Row],[Сумма Поддон]] -> 22990000 | O32: 700000 | P32: =Таблица1[[#This Row],[Цена Продажа]]-Таблица1[[#This Row],[Цена Приход]] -> 75000 | Q32: Фойда | R32: =Таблица1[[#This Row],[Блок Куб]]*Таблица1[[#This Row],[Цена Продажа]] -> 22982400 | S32: 2000000 | T32: =Таблица1[[#This Row],[Сумма Продажа]]-Таблица1[[#This Row],[Сумма Приход]] -> 2462400 | U32: 46207
A33: =A32+1 -> 30 | B33: Газоблок | C33: Жамол 22-22 | D33: Урганч Тамирлаш | E33: 46206 | F33: 90 K 295 QA | G33: 600x300x200 | H33: 32.832 | I33: 625000 | J33: =Таблица1[[#This Row],[Блок Куб]]*Таблица1[[#This Row],[Цена Приход]] -> 20520000 | K33: 19 | L33: 130000 | M33: =Таблица1[[#This Row],[Поддон Шт]]*Таблица1[[#This Row],[Цена Поддон]] -> 2470000 | N33: =Таблица1[[#This Row],[Сумма Приход]]+Таблица1[[#This Row],[Сумма Поддон]] -> 22990000 | O33: 700000 | P33: =Таблица1[[#This Row],[Цена Продажа]]-Таблица1[[#This Row],[Цена Приход]] -> 75000 | Q33: Фойда | R33: =Таблица1[[#This Row],[Блок Куб]]*Таблица1[[#This Row],[Цена Продажа]] -> 22982400 | T33: =Таблица1[[#This Row],[Сумма Продажа]]-Таблица1[[#This Row],[Сумма Приход]] -> 2462400
A34: =A33+1 -> 31 | B34: Газоблок | C34: Шохрух ога | D34: Рустам Шпик | E34: 46206 | F34: 90 015 WAA | G34: 600x300x200 | H34: 32.832 | I34: 625000 | J34: =Таблица1[[#This Row],[Блок Куб]]*Таблица1[[#This Row],[Цена Приход]] -> 20520000 | K34: 19 | L34: 130000 | M34: =Таблица1[[#This Row],[Поддон Шт]]*Таблица1[[#This Row],[Цена Поддон]] -> 2470000 | N34: =Таблица1[[#This Row],[Сумма Приход]]+Таблица1[[#This Row],[Сумма Поддон]] -> 22990000 | O34: 700000 | P34: =Таблица1[[#This Row],[Цена Продажа]]-Таблица1[[#This Row],[Цена Приход]] -> 75000 | Q34: Фойда | R34: =Таблица1[[#This Row],[Блок Куб]]*Таблица1[[#This Row],[Цена Продажа]] -> 22982400 | S34: 2000000 | T34: =Таблица1[[#This Row],[Сумма Продажа]]-Таблица1[[#This Row],[Сумма Приход]] -> 2462400 | U34: 46206
A35: =A34+1 -> 32 | B35: Газоблок | C35: Зафар ога | D35: Сулаймон Ога Хазарасп | E35: 46206 | F35: 90 452 PBA | G35: 600x300x200 | H35: 32.832 | I35: 625000 | J35: =Таблица1[[#This Row],[Блок Куб]]*Таблица1[[#This Row],[Цена Приход]] -> 20520000 | K35: 19 | L35: 130000 | M35: =Таблица1[[#This Row],[Поддон Шт]]*Таблица1[[#This Row],[Цена Поддон]] -> 2470000 | N35: =Таблица1[[#This Row],[Сумма Приход]]+Таблица1[[#This Row],[Сумма Поддон]] -> 22990000 | O35: 700000 | P35: =Таблица1[[#This Row],[Цена Продажа]]-Таблица1[[#This Row],[Цена Приход]] -> 75000 | Q35: Фойда | R35: =Таблица1[[#This Row],[Блок Куб]]*Таблица1[[#This Row],[Цена Продажа]] -> 22982400 | S35: клентдан | T35: =Таблица1[[#This Row],[Сумма Продажа]]-Таблица1[[#This Row],[Сумма Приход]] -> 2462400
A36: =A35+1 -> 33 | B36: Газоблок | C36: Шохрух ога | D36: Рустам Шпик | E36: 46206 | F36: 90 306 FBA | G36: 600x300x200 | H36: 32.832 | I36: 625000 | J36: =Таблица1[[#This Row],[Блок Куб]]*Таблица1[[#This Row],[Цена Приход]] -> 20520000 | K36: 19 | L36: 130000 | M36: =Таблица1[[#This Row],[Поддон Шт]]*Таблица1[[#This Row],[Цена Поддон]] -> 2470000 | N36: =Таблица1[[#This Row],[Сумма Приход]]+Таблица1[[#This Row],[Сумма Поддон]] -> 22990000 | O36: 700000 | P36: =Таблица1[[#This Row],[Цена Продажа]]-Таблица1[[#This Row],[Цена Приход]] -> 75000 | Q36: Фойда | R36: =Таблица1[[#This Row],[Блок Куб]]*Таблица1[[#This Row],[Цена Продажа]] -> 22982400 | S36: 2000000 | T36: =Таблица1[[#This Row],[Сумма Продажа]]-Таблица1[[#This Row],[Сумма Приход]] -> 2462400 | U36: 46207
A37: =A36+1 -> 34 | B37: Газоблок | C37: Жамол 22-22 | D37: Урганч Тамирлаш | E37: 46206 | F37: 90 N 831 HA | G37: 600x300x200 | H37: 32.832 | I37: 625000 | J37: =Таблица1[[#This Row],[Блок Куб]]*Таблица1[[#This Row],[Цена Приход]] -> 20520000 | K37: 19 | L37: 130000 | M37: =Таблица1[[#This Row],[Поддон Шт]]*Таблица1[[#This Row],[Цена Поддон]] -> 2470000 | N37: =Таблица1[[#This Row],[Сумма Приход]]+Таблица1[[#This Row],[Сумма Поддон]] -> 22990000 | O37: 700000 | P37: =Таблица1[[#This Row],[Цена Продажа]]-Таблица1[[#This Row],[Цена Приход]] -> 75000 | Q37: Фойда | R37: =Таблица1[[#This Row],[Блок Куб]]*Таблица1[[#This Row],[Цена Продажа]] -> 22982400 | T37: =Таблица1[[#This Row],[Сумма Продажа]]-Таблица1[[#This Row],[Сумма Приход]] -> 2462400
A38: =A37+1 -> 35 | B38: Газоблок | C38: Жамол 22-22 | D38: Урганч Тамирлаш | E38: 46206 | F38: 90 255 FBA | G38: 600x300x200 | H38: 32.832 | I38: 625000 | J38: =Таблица1[[#This Row],[Блок Куб]]*Таблица1[[#This Row],[Цена Приход]] -> 20520000 | K38: 19 | L38: 130000 | M38: =Таблица1[[#This Row],[Поддон Шт]]*Таблица1[[#This Row],[Цена Поддон]] -> 2470000 | N38: =Таблица1[[#This Row],[Сумма Приход]]+Таблица1[[#This Row],[Сумма Поддон]] -> 22990000 | O38: 700000 | P38: =Таблица1[[#This Row],[Цена Продажа]]-Таблица1[[#This Row],[Цена Приход]] -> 75000 | Q38: Фойда | R38: =Таблица1[[#This Row],[Блок Куб]]*Таблица1[[#This Row],[Цена Продажа]] -> 22982400 | S38: 2000000 | T38: =Таблица1[[#This Row],[Сумма Продажа]]-Таблица1[[#This Row],[Сумма Приход]] -> 2462400
A39: =A38+1 -> 36 | B39: Газоблок | C39: Зафар ога | D39: Сулаймон Ога Хазарасп | E39: 46206 | F39: 40 E 471 SB | G39: 600x300x100 | H39: 32.832 | I39: 625000 | J39: =Таблица1[[#This Row],[Блок Куб]]*Таблица1[[#This Row],[Цена Приход]] -> 20520000 | K39: 19 | L39: 130000 | M39: =Таблица1[[#This Row],[Поддон Шт]]*Таблица1[[#This Row],[Цена Поддон]] -> 2470000 | N39: =Таблица1[[#This Row],[Сумма Приход]]+Таблица1[[#This Row],[Сумма Поддон]] -> 22990000 | O39: 700000 | P39: =Таблица1[[#This Row],[Цена Продажа]]-Таблица1[[#This Row],[Цена Приход]] -> 75000 | Q39: Фойда | R39: =Таблица1[[#This Row],[Блок Куб]]*Таблица1[[#This Row],[Цена Продажа]] -> 22982400 | S39: клентдан | T39: =Таблица1[[#This Row],[Сумма Продажа]]-Таблица1[[#This Row],[Сумма Приход]] -> 2462400
A40: =A39+1 -> 37 | B40: Газоблок | C40: Зафар ога | D40: Сулаймон Ога Хазарасп | E40: 46206 | F40: 80 N 441 DB | G40: 600x300x200 | H40: 32.832 | I40: 625000 | J40: =Таблица1[[#This Row],[Блок Куб]]*Таблица1[[#This Row],[Цена Приход]] -> 20520000 | K40: 19 | L40: 130000 | M40: =Таблица1[[#This Row],[Поддон Шт]]*Таблица1[[#This Row],[Цена Поддон]] -> 2470000 | N40: =Таблица1[[#This Row],[Сумма Приход]]+Таблица1[[#This Row],[Сумма Поддон]] -> 22990000 | O40: 700000 | P40: =Таблица1[[#This Row],[Цена Продажа]]-Таблица1[[#This Row],[Цена Приход]] -> 75000 | Q40: Фойда | R40: =Таблица1[[#This Row],[Блок Куб]]*Таблица1[[#This Row],[Цена Продажа]] -> 22982400 | S40: клентдан | T40: =Таблица1[[#This Row],[Сумма Продажа]]-Таблица1[[#This Row],[Сумма Приход]] -> 2462400
A41: =A40+1 -> 38 | B41: Газоблок | C41: Темур | D41: Жасур Версал | E41: 46206 | F41: 80 C 385 CB | G41: 600x300x200 | H41: 32.832 | I41: 625000 | J41: =Таблица1[[#This Row],[Блок Куб]]*Таблица1[[#This Row],[Цена Приход]] -> 20520000 | K41: 19 | L41: 130000 | M41: =Таблица1[[#This Row],[Поддон Шт]]*Таблица1[[#This Row],[Цена Поддон]] -> 2470000 | N41: =Таблица1[[#This Row],[Сумма Приход]]+Таблица1[[#This Row],[Сумма Поддон]] -> 22990000 | O41: 700000 | P41: =Таблица1[[#This Row],[Цена Продажа]]-Таблица1[[#This Row],[Цена Приход]] -> 75000 | Q41: Фойда | R41: =Таблица1[[#This Row],[Блок Куб]]*Таблица1[[#This Row],[Цена Продажа]] -> 22982400 | S41: клентдан | T41: =Таблица1[[#This Row],[Сумма Продажа]]-Таблица1[[#This Row],[Сумма Приход]] -> 2462400
A42: =A41+1 -> 39 | B42: Газоблок | C42: Темур | D42: Жасур Версал | E42: 46206 | F42: 90 S 954 OA | G42: 600x300x200 | H42: 32.832 | I42: 625000 | J42: =Таблица1[[#This Row],[Блок Куб]]*Таблица1[[#This Row],[Цена Приход]] -> 20520000 | K42: 19 | L42: 130000 | M42: =Таблица1[[#This Row],[Поддон Шт]]*Таблица1[[#This Row],[Цена Поддон]] -> 2470000 | N42: =Таблица1[[#This Row],[Сумма Приход]]+Таблица1[[#This Row],[Сумма Поддон]] -> 22990000 | O42: 700000 | P42: =Таблица1[[#This Row],[Цена Продажа]]-Таблица1[[#This Row],[Цена Приход]] -> 75000 | Q42: Фойда | R42: =Таблица1[[#This Row],[Блок Куб]]*Таблица1[[#This Row],[Цена Продажа]] -> 22982400 | S42: клентдан | T42: =Таблица1[[#This Row],[Сумма Продажа]]-Таблица1[[#This Row],[Сумма Приход]] -> 2462400
A43: =A42+1 -> 40 | B43: Газоблок | C43: Темур | D43: Жасур Версал | E43: 46206 | F43: 90 734 МВА | G43: 600x300x100 | H43: 32.832 | I43: 625000 | J43: =Таблица1[[#This Row],[Блок Куб]]*Таблица1[[#This Row],[Цена Приход]] -> 20520000 | K43: 19 | L43: 130000 | M43: =Таблица1[[#This Row],[Поддон Шт]]*Таблица1[[#This Row],[Цена Поддон]] -> 2470000 | N43: =Таблица1[[#This Row],[Сумма Приход]]+Таблица1[[#This Row],[Сумма Поддон]] -> 22990000 | O43: 700000 | P43: =Таблица1[[#This Row],[Цена Продажа]]-Таблица1[[#This Row],[Цена Приход]] -> 75000 | Q43: Фойда | R43: =Таблица1[[#This Row],[Блок Куб]]*Таблица1[[#This Row],[Цена Продажа]] -> 22982400 | S43: клентдан | T43: =Таблица1[[#This Row],[Сумма Продажа]]-Таблица1[[#This Row],[Сумма Приход]] -> 2462400
A44: =A43+1 -> 41 | B44: Газоблок | C44: Зафар ога | D44: Сарвар ога Шовот | E44: 46209 | F44: 90 015 WAA | G44: 600x300x200 | H44: 32.832 | I44: 625000 | J44: =Таблица1[[#This Row],[Блок Куб]]*Таблица1[[#This Row],[Цена Приход]] -> 20520000 | K44: 19 | L44: 130000 | M44: =Таблица1[[#This Row],[Поддон Шт]]*Таблица1[[#This Row],[Цена Поддон]] -> 2470000 | N44: =Таблица1[[#This Row],[Сумма Приход]]+Таблица1[[#This Row],[Сумма Поддон]] -> 22990000 | O44: 700000 | P44: =Таблица1[[#This Row],[Цена Продажа]]-Таблица1[[#This Row],[Цена Приход]] -> 75000 | Q44: Фойда | R44: =Таблица1[[#This Row],[Блок Куб]]*Таблица1[[#This Row],[Цена Продажа]] -> 22982400 | S44: клентдан | T44: =Таблица1[[#This Row],[Сумма Продажа]]-Таблица1[[#This Row],[Сумма Приход]] -> 2462400
A45: =A44+1 -> 42 | B45: Газоблок | C45: Темур | D45: Мустафо машал | E45: 46209 | F45: 40 O 636 TB | G45: 600x300x200 | H45: 32.832 | I45: 625000 | J45: =Таблица1[[#This Row],[Блок Куб]]*Таблица1[[#This Row],[Цена Приход]] -> 20520000 | K45: 19 | L45: 130000 | M45: =Таблица1[[#This Row],[Поддон Шт]]*Таблица1[[#This Row],[Цена Поддон]] -> 2470000 | N45: =Таблица1[[#This Row],[Сумма Приход]]+Таблица1[[#This Row],[Сумма Поддон]] -> 22990000 | O45: 700000 | P45: =Таблица1[[#This Row],[Цена Продажа]]-Таблица1[[#This Row],[Цена Приход]] -> 75000 | Q45: Фойда | R45: =Таблица1[[#This Row],[Блок Куб]]*Таблица1[[#This Row],[Цена Продажа]] -> 22982400 | S45: клентдан | T45: =Таблица1[[#This Row],[Сумма Продажа]]-Таблица1[[#This Row],[Сумма Приход]] -> 2462400
A46: =A45+1 -> 43 | B46: Газоблок | C46: Арслон ога | D46: Шиддат моналит | E46: 46209 | F46: 85 L 457 HA | G46: 600x300x250 | H46: 23.4 | I46: 625000 | J46: =Таблица1[[#This Row],[Блок Куб]]*Таблица1[[#This Row],[Цена Приход]] -> 14625000 | K46: 13 | L46: 130000 | M46: =Таблица1[[#This Row],[Поддон Шт]]*Таблица1[[#This Row],[Цена Поддон]] -> 1690000 | N46: =Таблица1[[#This Row],[Сумма Приход]]+Таблица1[[#This Row],[Сумма Поддон]] -> 16315000 | O46: 700000 | P46: =Таблица1[[#This Row],[Цена Продажа]]-Таблица1[[#This Row],[Цена Приход]] -> 75000 | Q46: Фойда | R46: =Таблица1[[#This Row],[Блок Куб]]*Таблица1[[#This Row],[Цена Продажа]] -> 16380000 | T46: =Таблица1[[#This Row],[Сумма Продажа]]-Таблица1[[#This Row],[Сумма Приход]] -> 1755000
A47: =A46+1 -> 44 | B47: Газоблок | C47: Арслон ога | D47: Шиддат моналит | E47: 46209 | F47: 85 L 457 HA | G47: 600x300x200 | H47: 10.37 | I47: 625000 | J47: =Таблица1[[#This Row],[Блок Куб]]*Таблица1[[#This Row],[Цена Приход]] -> 6481250 | K47: 6 | L47: 130000 | M47: =Таблица1[[#This Row],[Поддон Шт]]*Таблица1[[#This Row],[Цена Поддон]] -> 780000 | N47: =Таблица1[[#This Row],[Сумма Приход]]+Таблица1[[#This Row],[Сумма Поддон]] -> 7261250 | O47: 700000 | P47: =Таблица1[[#This Row],[Цена Продажа]]-Таблица1[[#This Row],[Цена Приход]] -> 75000 | Q47: Фойда | R47: =Таблица1[[#This Row],[Блок Куб]]*Таблица1[[#This Row],[Цена Продажа]] -> 7259000 | T47: =Таблица1[[#This Row],[Сумма Продажа]]-Таблица1[[#This Row],[Сумма Приход]] -> 777750
A48: =A47+1 -> 45 | B48: Газоблок | C48: Зафар ога | D48: Сулаймон Ога Хазарасп | E48: 46209 | F48: 95 N 260 OA | G48: 600x300x200 | H48: 32.832 | I48: 625000 | J48: =Таблица1[[#This Row],[Блок Куб]]*Таблица1[[#This Row],[Цена Приход]] -> 20520000 | K48: 19 | L48: 130000 | M48: =Таблица1[[#This Row],[Поддон Шт]]*Таблица1[[#This Row],[Цена Поддон]] -> 2470000 | N48: =Таблица1[[#This Row],[Сумма Приход]]+Таблица1[[#This Row],[Сумма Поддон]] -> 22990000 | O48: 700000 | P48: =Таблица1[[#This Row],[Цена Продажа]]-Таблица1[[#This Row],[Цена Приход]] -> 75000 | Q48: Фойда | R48: =Таблица1[[#This Row],[Блок Куб]]*Таблица1[[#This Row],[Цена Продажа]] -> 22982400 | S48: клентдан | T48: =Таблица1[[#This Row],[Сумма Продажа]]-Таблица1[[#This Row],[Сумма Приход]] -> 2462400
A49: =A48+1 -> 46 | B49: Газоблок | C49: Темур | D49: Жасур Версал | E49: 46209 | F49: 95 C 626 SA | G49: 600x300x100 | H49: 32.832 | I49: 625000 | J49: =Таблица1[[#This Row],[Блок Куб]]*Таблица1[[#This Row],[Цена Приход]] -> 20520000 | K49: 19 | L49: 130000 | M49: =Таблица1[[#This Row],[Поддон Шт]]*Таблица1[[#This Row],[Цена Поддон]] -> 2470000 | N49: =Таблица1[[#This Row],[Сумма Приход]]+Таблица1[[#This Row],[Сумма Поддон]] -> 22990000 | O49: 700000 | P49: =Таблица1[[#This Row],[Цена Продажа]]-Таблица1[[#This Row],[Цена Приход]] -> 75000 | Q49: Фойда | R49: =Таблица1[[#This Row],[Блок Куб]]*Таблица1[[#This Row],[Цена Продажа]] -> 22982400 | T49: =Таблица1[[#This Row],[Сумма Продажа]]-Таблица1[[#This Row],[Сумма Приход]] -> 2462400
A50: =A49+1 -> 47 | B50: Газоблок | C50: Темур | D50: Жасур Версал | E50: 46210 | F50: 90 Z 410 ZZ | G50: 600x300x100 | H50: 32.832 | I50: 625000 | J50: =Таблица1[[#This Row],[Блок Куб]]*Таблица1[[#This Row],[Цена Приход]] -> 20520000 | K50: 19 | L50: 130000 | M50: =Таблица1[[#This Row],[Поддон Шт]]*Таблица1[[#This Row],[Цена Поддон]] -> 2470000 | N50: =Таблица1[[#This Row],[Сумма Приход]]+Таблица1[[#This Row],[Сумма Поддон]] -> 22990000 | O50: 700000 | P50: =Таблица1[[#This Row],[Цена Продажа]]-Таблица1[[#This Row],[Цена Приход]] -> 75000 | Q50: Фойда | R50: =Таблица1[[#This Row],[Блок Куб]]*Таблица1[[#This Row],[Цена Продажа]] -> 22982400 | T50: =Таблица1[[#This Row],[Сумма Продажа]]-Таблица1[[#This Row],[Сумма Приход]] -> 2462400
...

Sheet 1-Урганч Тамирлаш
D1: 1-Урганч Тамирлаш
A2: ID-Клиента | F2: =Таблица2133990[[#Totals],[2]]+-Таблица2133990[[#Totals],[16]] -> -6929600
A3: № | B3: Дата | C3: Сумма | D3: Перемечание | E3: Возврат паддон | F3: № | G3: Дата | H3: Авто | I3: Размер | J3: Блок Куб | K3: Поддон Шт | L3: Цена Продажа | M3: Сумма
C5: =Таблица2133990[[#Totals],[2]] -> 130570000 | E5: =SUM(Таблица2133990[4]) -> 0 | K5: =Таблица2133990[[#Totals],[1132]] -> 112 | M5: =Таблица2133990[[#Totals],[16]] -> 1.374996e+08
B6: 1 | C6: 2 | D6: 3 | E6: 4 | F6: 9 | G6: 10 | H6: 11 | I6: 114 | J6: 113 | K6: 1132 | L6: 15 | M6: 16
A7: 1 | C7: 45570000 | F7: =Таблица2133990[[#This Row],[ ]] -> 1 | G7: 46197 | H7: 95 G 851 NA | I7: 600x300x200 | J7: 31.104 | K7: 18 | L7: 732542.44 | M7: =Таблица2133990[[#This Row],[113]]*(Таблица2133990[[#This Row],[15]]) -> 22785000
A8: 2 | B8: 46206 | C8: 85000000 | D8: URGANCH TAMIRLASH | F8: =Таблица2133990[[#This Row],[ ]] -> 2 | G8: 46197 | H8: 40 Y 173 KB | I8: 600x300x200 | J8: 31.104 | K8: 18 | L8: 732542.44 | M8: =Таблица2133990[[#This Row],[113]]*(Таблица2133990[[#This Row],[15]]) -> 22785000
A9: 3 | F9: =Таблица2133990[[#This Row],[ ]] -> 3 | G9: 46206 | H9: 40 F 105 RB | I9: 600x300x200 | J9: 32.832 | K9: 19 | L9: 700000 | M9: =Таблица2133990[[#This Row],[113]]*(Таблица2133990[[#This Row],[15]]) -> 22982400
A10: 4 | F10: =Таблица2133990[[#This Row],[ ]] -> 4 | G10: 46206 | H10: 90 K 295 QA | I10: 600x300x200 | J10: 32.832 | K10: 19 | L10: 700000 | M10: =Таблица2133990[[#This Row],[113]]*(Таблица2133990[[#This Row],[15]]) -> 22982400
A11: 5 | F11: =Таблица2133990[[#This Row],[ ]] -> 5 | G11: 46206 | H11: 90 N 831 HA | I11: 600x300x200 | J11: 32.832 | K11: 19 | L11: 700000 | M11: =Таблица2133990[[#This Row],[113]]*(Таблица2133990[[#This Row],[15]]) -> 22982400
A12: 6 | F12: =Таблица2133990[[#This Row],[ ]] -> 6 | G12: 46206 | H12: 90 255 FBA | I12: 600x300x200 | J12: 32.832 | K12: 19 | L12: 700000 | M12: =Таблица2133990[[#This Row],[113]]*(Таблица2133990[[#This Row],[15]]) -> 22982400
A13: 7 | F13: =Таблица2133990[[#This Row],[ ]] -> 7 | M13: =Таблица2133990[[#This Row],[113]]*(Таблица2133990[[#This Row],[15]]) -> 0
A14: 8 | F14: =Таблица2133990[[#This Row],[ ]] -> 8 | M14: =Таблица2133990[[#This Row],[113]]*(Таблица2133990[[#This Row],[15]]) -> 0
A15: 9 | F15: =Таблица2133990[[#This Row],[ ]] -> 9 | M15: =Таблица2133990[[#This Row],[113]]*(Таблица2133990[[#This Row],[15]]) -> 0
A16: 10 | F16: =Таблица2133990[[#This Row],[ ]] -> 10 | M16: =Таблица2133990[[#This Row],[113]]*(Таблица2133990[[#This Row],[15]]) -> 0
A17: 11 | F17: =Таблица2133990[[#This Row],[ ]] -> 11 | M17: =Таблица2133990[[#This Row],[113]]*(Таблица2133990[[#This Row],[15]]) -> 0
A18: 12 | F18: =Таблица2133990[[#This Row],[ ]] -> 12 | M18: =Таблица2133990[[#This Row],[113]]*(Таблица2133990[[#This Row],[15]]) -> 0
A19: 13 | F19: =Таблица2133990[[#This Row],[ ]] -> 13 | M19: =Таблица2133990[[#This Row],[113]]*(Таблица2133990[[#This Row],[15]]) -> 0
A20: 14 | F20: =Таблица2133990[[#This Row],[ ]] -> 14 | M20: =Таблица2133990[[#This Row],[113]]*(Таблица2133990[[#This Row],[15]]) -> 0
A21: 15 | F21: =Таблица2133990[[#This Row],[ ]] -> 15 | M21: =Таблица2133990[[#This Row],[113]]*(Таблица2133990[[#This Row],[15]]) -> 0
A22: 16 | F22: =Таблица2133990[[#This Row],[ ]] -> 16 | M22: =Таблица2133990[[#This Row],[113]]*(Таблица2133990[[#This Row],[15]]) -> 0
A23: 17 | F23: =Таблица2133990[[#This Row],[ ]] -> 17 | M23: =Таблица2133990[[#This Row],[113]]*(Таблица2133990[[#This Row],[15]]) -> 0
A24: 18 | F24: =Таблица2133990[[#This Row],[ ]] -> 18 | M24: =Таблица2133990[[#This Row],[113]]*(Таблица2133990[[#This Row],[15]]) -> 0
... A49: 43 | F49: =Таблица2133990[[#This Row],[ ]] -> 43 | M49: =Таблица2133990[[#This Row],[113]]*(Таблица2133990[[#This Row],[15]]) -> 0
C50: =SUBTOTAL(109,Таблица2133990[2]) -> 130570000 | K50: =SUBTOTAL(109,Таблица2133990[1132]) -> 112 | M50: =SUBTOTAL(109,Таблица2133990[16]) -> 1.374996e+08

Sheet 1-Инвест Холдинг
D1: 1-Инвест Холдинг
A2: ID-Клиента | F2: =Таблица213399028[[#Totals],[2]]+-Таблица213399028[[#Totals],[16]] -> 0
A3: № | B3: Дата | C3: Сумма | D3: Примечание | E3: Возврат паддон | F3: № | G3: Дата | H3: Авто | I3: Размер | J3: Блок Куб | K3: Поддон Шт | L3: От | M3: Сумма
C5: =Таблица213399028[[#Totals],[2]] -> 67737600 | E5: =SUM(Таблица213399028[4]) -> 0 | K5: =Таблица213399028[[#Totals],[1132]] -> 56 | M5: =Таблица213399028[[#Totals],[16]] -> 67737600
B6: 1 | C6: 2 | D6: 3 | E6: 4 | F6: 9 | G6: 10 | H6: 11 | I6: 114 | J6: 113 | K6: 1132 | L6: 15 | M6: 16
A7: 1 | B7: 46205 | C7: 67737600 | D7: Хоразм Инвест Холдинг | F7: =Таблица213399028[[#This Row],[ ]] -> 1 | G7: 46197 | H7: 90 X 700 CA | I7: 600x300x200 | J7: 31.104 | K7: 18 | L7: 700000 | M7: =Таблица213399028[[#This Row],[113]]*Таблица213399028[[#This Row],[15]] -> 21772800
A8: 2 | F8: =Таблица213399028[[#This Row],[ ]] -> 2 | G8: 46197 | H8: 90 G 429 CA | I8: 600x300x200 | J8: 32.832 | K8: 19 | L8: 700000 | M8: =Таблица213399028[[#This Row],[113]]*Таблица213399028[[#This Row],[15]] -> 22982400
A9: 3 | F9: =Таблица213399028[[#This Row],[ ]] -> 3 | G9: 46198 | H9: 30 N 113 MB | I9: 600x300x200 | J9: 32.832 | K9: 19 | L9: 700000 | M9: =Таблица213399028[[#This Row],[113]]*Таблица213399028[[#This Row],[15]] -> 22982400
A10: 4 | F10: =Таблица213399028[[#This Row],[ ]] -> 4 | M10: =Таблица213399028[[#This Row],[113]]*Таблица213399028[[#This Row],[15]] -> 0
A11: 5 | F11: =Таблица213399028[[#This Row],[ ]] -> 5 | M11: =Таблица213399028[[#This Row],[113]]*Таблица213399028[[#This Row],[15]] -> 0
A12: 6 | F12: =Таблица213399028[[#This Row],[ ]] -> 6 | M12: =Таблица213399028[[#This Row],[113]]*Таблица213399028[[#This Row],[15]] -> 0
A13: 7 | F13: =Таблица213399028[[#This Row],[ ]] -> 7 | M13: =Таблица213399028[[#This Row],[113]]*Таблица213399028[[#This Row],[15]] -> 0
A14: 8 | F14: =Таблица213399028[[#This Row],[ ]] -> 8 | M14: =Таблица213399028[[#This Row],[113]]*Таблица213399028[[#This Row],[15]] -> 0
A15: 9 | F15: =Таблица213399028[[#This Row],[ ]] -> 9 | M15: =Таблица213399028[[#This Row],[113]]*Таблица213399028[[#This Row],[15]] -> 0
A16: 10 | F16: =Таблица213399028[[#This Row],[ ]] -> 10 | M16: =Таблица213399028[[#This Row],[113]]*Таблица213399028[[#This Row],[15]] -> 0
A17: 11 | F17: =Таблица213399028[[#This Row],[ ]] -> 11 | M17: =Таблица213399028[[#This Row],[113]]*Таблица213399028[[#This Row],[15]] -> 0
A18: 12 | F18: =Таблица213399028[[#This Row],[ ]] -> 12 | M18: =Таблица213399028[[#This Row],[113]]*Таблица213399028[[#This Row],[15]] -> 0
A19: 13 | F19: =Таблица213399028[[#This Row],[ ]] -> 13 | M19: =Таблица213399028[[#This Row],[113]]*Таблица213399028[[#This Row],[15]] -> 0
A20: 14 | F20: =Таблица213399028[[#This Row],[ ]] -> 14 | M20: =Таблица213399028[[#This Row],[113]]*Таблица213399028[[#This Row],[15]] -> 0
A21: 15 | F21: =Таблица213399028[[#This Row],[ ]] -> 15 | M21: =Таблица213399028[[#This Row],[113]]*Таблица213399028[[#This Row],[15]] -> 0
... A49: 43 | F49: =Таблица213399028[[#This Row],[ ]] -> 43 | M49: =Таблица213399028[[#This Row],[113]]*Таблица213399028[[#This Row],[15]] -> 0
C50: =SUBTOTAL(109,Таблица213399028[2]) -> 67737600 | K50: =SUBTOTAL(109,Таблица213399028[1132]) -> 56 | M50: =SUBTOTAL(109,Таблица213399028[16]) -> 67737600

Sheet 1-Нормат Умидбек
D1: 1-Нормат Умидбек
A2: ID-Клиента | F2: =Таблица213399029[[#Totals],[2]]+-Таблица213399029[[#Totals],[16]] -> 0
A3: № | B3: Дата | C3: Сумма | D3: Примечание | E3: Возврат паддон | F3: № | G3: Дата | H3: Авто | I3: Размер | J3: Блок Куб | K3: Поддон Шт | L3: От | M3: Сумма
C5: =Таблица213399029[[#Totals],[2]] -> 72394560 | E5: =SUM(Таблица213399029[4]) -> 0 | K5: =Таблица213399029[[#Totals],[1132]] -> 57 | M5: =Таблица213399029[[#Totals],[16]] -> 72394560
B6: 1 | C6: 2 | D6: 3 | E6: 4 | F6: 9 | G6: 10 | H6: 11 | I6: 114 | J6: 113 | K6: 1132 | L6: 15 | M6: 16
A7: 1 | B7: 46205 | C7: 72394560 | D7: NORMAT UMIDBEK MCHJ | F7: =Таблица213399029[[#This Row],[ ]] -> 1 | G7: 46198 | H7: 50 R 575 CB | I7: 600x300x200 | J7: 32.832 | K7: 19 | L7: 735000 | M7: =Таблица213399029[[#This Row],[113]]*Таблица213399029[[#This Row],[15]] -> 24131520
A8: 2 | F8: =Таблица213399029[[#This Row],[ ]] -> 2 | G8: 46198 | H8: 30 784 WBA | I8: 600x300x200 | J8: 32.832 | K8: 19 | L8: 735000 | M8: =Таблица213399029[[#This Row],[113]]*Таблица213399029[[#This Row],[15]] -> 24131520
A9: 3 | F9: =Таблица213399029[[#This Row],[ ]] -> 3 | G9: 46198 | H9: VI-004-KT | I9: 600x300x200 | J9: 32.832 | K9: 19 | L9: 735000 | M9: =Таблица213399029[[#This Row],[113]]*Таблица213399029[[#This Row],[15]] -> 24131520
A10: 4 | F10: =Таблица213399029[[#This Row],[ ]] -> 4 | M10: =Таблица213399029[[#This Row],[113]]*Таблица213399029[[#This Row],[15]] -> 0
A11: 5 | F11: =Таблица213399029[[#This Row],[ ]] -> 5 | M11: =Таблица213399029[[#This Row],[113]]*Таблица213399029[[#This Row],[15]] -> 0
A12: 6 | F12: =Таблица213399029[[#This Row],[ ]] -> 6 | M12: =Таблица213399029[[#This Row],[113]]*Таблица213399029[[#This Row],[15]] -> 0
A13: 7 | F13: =Таблица213399029[[#This Row],[ ]] -> 7 | M13: =Таблица213399029[[#This Row],[113]]*Таблица213399029[[#This Row],[15]] -> 0
A14: 8 | F14: =Таблица213399029[[#This Row],[ ]] -> 8 | M14: =Таблица213399029[[#This Row],[113]]*Таблица213399029[[#This Row],[15]] -> 0
A15: 9 | F15: =Таблица213399029[[#This Row],[ ]] -> 9 | M15: =Таблица213399029[[#This Row],[113]]*Таблица213399029[[#This Row],[15]] -> 0
A16: 10 | F16: =Таблица213399029[[#This Row],[ ]] -> 10 | M16: =Таблица213399029[[#This Row],[113]]*Таблица213399029[[#This Row],[15]] -> 0
A17: 11 | F17: =Таблица213399029[[#This Row],[ ]] -> 11 | M17: =Таблица213399029[[#This Row],[113]]*Таблица213399029[[#This Row],[15]] -> 0
A18: 12 | F18: =Таблица213399029[[#This Row],[ ]] -> 12 | M18: =Таблица213399029[[#This Row],[113]]*Таблица213399029[[#This Row],[15]] -> 0
A19: 13 | F19: =Таблица213399029[[#This Row],[ ]] -> 13 | M19: =Таблица213399029[[#This Row],[113]]*Таблица213399029[[#This Row],[15]] -> 0
A20: 14 | F20: =Таблица213399029[[#This Row],[ ]] -> 14 | M20: =Таблица213399029[[#This Row],[113]]*Таблица213399029[[#This Row],[15]] -> 0
A21: 15 | F21: =Таблица213399029[[#This Row],[ ]] -> 15 | M21: =Таблица213399029[[#This Row],[113]]*Таблица213399029[[#This Row],[15]] -> 0
... A49: 43 | F49: =Таблица213399029[[#This Row],[ ]] -> 43 | M49: =Таблица213399029[[#This Row],[113]]*Таблица213399029[[#This Row],[15]] -> 0
C50: =SUBTOTAL(109,Таблица213399029[2]) -> 72394560 | K50: =SUBTOTAL(109,Таблица213399029[1132]) -> 57 | M50: =SUBTOTAL(109,Таблица213399029[16]) -> 72394560

Sheet 1-Ирригатсия темир бетон
D1: 1-Ирригатсия темир бетон
A2: ID-Клиента | F2: =Таблица2133990291011[[#Totals],[2]]+-Таблица2133990291011[[#Totals],[16]] -> 8700480
A3: № | B3: Дата | C3: Сумма | D3: Примечание | E3: Возврат паддон | F3: № | G3: Дата | H3: Авто | I3: Размер | J3: Блок Куб | K3: Поддон Шт | L3: От | M3: Сумма
C5: =Таблица2133990291011[[#Totals],[2]] -> 32832000 | E5: =SUM(Таблица2133990291011[4]) -> 0 | K5: =Таблица2133990291011[[#Totals],[1132]] -> 19 | M5: =Таблица2133990291011[[#Totals],[16]] -> 24131520
B6: 1 | C6: 2 | D6: 3 | E6: 4 | F6: 9 | G6: 10 | H6: 11 | I6: 114 | J6: 113 | K6: 1132 | L6: 15 | M6: 16
A7: 1 | B7: 46211 | C7: 32832000 | D7: Ирригатсия темир бетон | F7: =Таблица2133990291011[[#This Row],[ ]] -> 1 | G7: 46203 | H7: 25 Q 068 OA | I7: 600x300x200 | J7: 32.832 | K7: 19 | L7: 735000 | M7: =Таблица2133990291011[[#This Row],[113]]*Таблица2133990291011[[#This Row],[15]] -> 24131520
A8: 2 | F8: =Таблица2133990291011[[#This Row],[ ]] -> 2 | M8: =Таблица2133990291011[[#This Row],[113]]*Таблица2133990291011[[#This Row],[15]] -> 0
A9: 3 | F9: =Таблица2133990291011[[#This Row],[ ]] -> 3 | M9: =Таблица2133990291011[[#This Row],[113]]*Таблица2133990291011[[#This Row],[15]] -> 0
A10: 4 | F10: =Таблица2133990291011[[#This Row],[ ]] -> 4 | M10: =Таблица2133990291011[[#This Row],[113]]*Таблица2133990291011[[#This Row],[15]] -> 0
A11: 5 | F11: =Таблица2133990291011[[#This Row],[ ]] -> 5 | M11: =Таблица2133990291011[[#This Row],[113]]*Таблица2133990291011[[#This Row],[15]] -> 0
